<?xml version="1.0" ?>
<robot name="autorobo" xmlns:xacro="http://www.ros.org/wiki/xacro">

<xacro:include filename="$(find autorobo_description)/urdf/materials.xacro" />
<xacro:include filename="$(find autorobo_description)/urdf/autorobo.trans" />
<xacro:include filename="$(find autorobo_description)/urdf/autorobo.gazebo" />
<link name="base_link">
  <inertial>
    <origin rpy="0 0 0" xyz="0.003390926891335506 -0.00033516323150329654 0.01902854121941396"/>
    <mass value="0.1986894956353715"/>
    <inertia ixx="0.000463" ixy="0.0" ixz="0.0" iyy="0.001178" iyz="-0.0" izz="0.00164"/>
  </inertial>
  <visual>
    <origin rpy="0 0 0" xyz="0 0 0"/>
    <geometry>
      <mesh filename="package://autorobo_description/meshes/base_link.stl" scale="0.001 0.001 0.001"/>
    </geometry>
    <material name="silver"/>
  </visual>
  <collision>
    <origin rpy="0 0 0" xyz="0 0 0"/>
    <geometry>
      <mesh filename="package://autorobo_description/meshes/base_link.stl" scale="0.001 0.001 0.001"/>
    </geometry>
  </collision>
</link>

<link name="ST14_1_1">
  <inertial>
    <origin rpy="0 0 0" xyz="-0.01000020610561446 -0.019999688418160168 0.02999974313705814"/>
    <mass value="0.04411533406877944"/>
    <inertia ixx="1.4e-05" ixy="0.0" ixz="0.0" iyy="1.4e-05" iyz="0.0" izz="1e-06"/>
  </inertial>
  <visual>
    <origin rpy="0 0 0" xyz="-0.103397 -0.069664 -0.021028"/>
    <geometry>
      <mesh filename="package://autorobo_description/meshes/ST14_1_1.stl" scale="0.001 0.001 0.001"/>
    </geometry>
    <material name="silver"/>
  </visual>
  <collision>
    <origin rpy="0 0 0" xyz="-0.103397 -0.069664 -0.021028"/>
    <geometry>
      <mesh filename="package://autorobo_description/meshes/ST14_1_1.stl" scale="0.001 0.001 0.001"/>
    </geometry>
  </collision>
</link>

<link name="ST13_1_1">
  <inertial>
    <origin rpy="0 0 0" xyz="0.009999793894385517 -0.01999968841816003 0.02999974313705815"/>
    <mass value="0.044115334068779405"/>
    <inertia ixx="1.4e-05" ixy="0.0" ixz="-0.0" iyy="1.4e-05" iyz="0.0" izz="1e-06"/>
  </inertial>
  <visual>
    <origin rpy="0 0 0" xyz="0.096603 -0.069664 -0.021028"/>
    <geometry>
      <mesh filename="package://autorobo_description/meshes/ST13_1_1.stl" scale="0.001 0.001 0.001"/>
    </geometry>
    <material name="silver"/>
  </visual>
  <collision>
    <origin rpy="0 0 0" xyz="0.096603 -0.069664 -0.021028"/>
    <geometry>
      <mesh filename="package://autorobo_description/meshes/ST13_1_1.stl" scale="0.001 0.001 0.001"/>
    </geometry>
  </collision>
</link>

<link name="ST12_1_1">
  <inertial>
    <origin rpy="0 0 0" xyz="0.009999793894385475 0.02000031158183989 0.029999743137057635"/>
    <mass value="0.04411533406877944"/>
    <inertia ixx="1.4e-05" ixy="-0.0" ixz="0.0" iyy="1.4e-05" iyz="0.0" izz="1e-06"/>
  </inertial>
  <visual>
    <origin rpy="0 0 0" xyz="0.096603 0.070336 -0.021028"/>
    <geometry>
      <mesh filename="package://autorobo_description/meshes/ST12_1_1.stl" scale="0.001 0.001 0.001"/>
    </geometry>
    <material name="silver"/>
  </visual>
  <collision>
    <origin rpy="0 0 0" xyz="0.096603 0.070336 -0.021028"/>
    <geometry>
      <mesh filename="package://autorobo_description/meshes/ST12_1_1.stl" scale="0.001 0.001 0.001"/>
    </geometry>
  </collision>
</link>

<link name="BRM_1_1">
  <inertial>
    <origin rpy="0 0 0" xyz="-0.05844982226375398 -0.03739349041636441 0.013184742392542425"/>
    <mass value="0.22883774452212485"/>
    <inertia ixx="7.9e-05" ixy="5e-06" ixz="-0.0" iyy="2.1e-05" iyz="1e-06" izz="8.2e-05"/>
  </inertial>
  <visual>
    <origin rpy="0 0 0" xyz="-0.003397 0.000336 -0.021028"/>
    <geometry>
      <mesh filename="package://autorobo_description/meshes/BRM_1_1.stl" scale="0.001 0.001 0.001"/>
    </geometry>
    <material name="silver"/>
  </visual>
  <collision>
    <origin rpy="0 0 0" xyz="-0.003397 0.000336 -0.021028"/>
    <geometry>
      <mesh filename="package://autorobo_description/meshes/BRM_1_1.stl" scale="0.001 0.001 0.001"/>
    </geometry>
  </collision>
</link>

<link name="BLM_1_1">
  <inertial>
    <origin rpy="0 0 0" xyz="-0.058449822248107665 0.03739411358004443 0.013184742392542612"/>
    <mass value="0.22883774452212463"/>
    <inertia ixx="7.9e-05" ixy="-5e-06" ixz="-0.0" iyy="2.1e-05" iyz="-1e-06" izz="8.2e-05"/>
  </inertial>
  <visual>
    <origin rpy="0 0 0" xyz="-0.002697 0.000336 -0.021028"/>
    <geometry>
      <mesh filename="package://autorobo_description/meshes/BLM_1_1.stl" scale="0.001 0.001 0.001"/>
    </geometry>
    <material name="silver"/>
  </visual>
  <collision>
    <origin rpy="0 0 0" xyz="-0.002697 0.000336 -0.021028"/>
    <geometry>
      <mesh filename="package://autorobo_description/meshes/BLM_1_1.stl" scale="0.001 0.001 0.001"/>
    </geometry>
  </collision>
</link>

<link name="FRM_1_1">
  <inertial>
    <origin rpy="0 0 0" xyz="0.05844941006817119 -0.03739349041636451 0.013184742392542376"/>
    <mass value="0.22883774452212488"/>
    <inertia ixx="7.9e-05" ixy="-5e-06" ixz="0.0" iyy="2.1e-05" iyz="1e-06" izz="8.2e-05"/>
  </inertial>
  <visual>
    <origin rpy="0 0 0" xyz="-0.002697 0.000336 -0.021028"/>
    <geometry>
      <mesh filename="package://autorobo_description/meshes/FRM_1_1.stl" scale="0.001 0.001 0.001"/>
    </geometry>
    <material name="silver"/>
  </visual>
  <collision>
    <origin rpy="0 0 0" xyz="-0.002697 0.000336 -0.021028"/>
    <geometry>
      <mesh filename="package://autorobo_description/meshes/FRM_1_1.stl" scale="0.001 0.001 0.001"/>
    </geometry>
  </collision>
</link>

<link name="FLM_1_1">
  <inertial>
    <origin rpy="0 0 0" xyz="0.05844941005252506 0.037394113580044304 0.013184742392542814"/>
    <mass value="0.22883774452212455"/>
    <inertia ixx="7.9e-05" ixy="5e-06" ixz="0.0" iyy="2.1e-05" iyz="-1e-06" izz="8.2e-05"/>
  </inertial>
  <visual>
    <origin rpy="0 0 0" xyz="-0.003397 0.000336 -0.021028"/>
    <geometry>
      <mesh filename="package://autorobo_description/meshes/FLM_1_1.stl" scale="0.001 0.001 0.001"/>
    </geometry>
    <material name="silver"/>
  </visual>
  <collision>
    <origin rpy="0 0 0" xyz="-0.003397 0.000336 -0.021028"/>
    <geometry>
      <mesh filename="package://autorobo_description/meshes/FLM_1_1.stl" scale="0.001 0.001 0.001"/>
    </geometry>
  </collision>
</link>

<link name="l298n_1_1">
  <inertial>
    <origin rpy="0 0 0" xyz="0.018184118265183444 -0.016389590081724772 0.007470505450688978"/>
    <mass value="0.0849456744695859"/>
    <inertia ixx="1.7e-05" ixy="-0.0" ixz="0.0" iyy="1.4e-05" iyz="-3e-06" izz="2.3e-05"/>
  </inertial>
  <visual>
    <origin rpy="0 0 0" xyz="0.015 0.02 -0.022028"/>
    <geometry>
      <mesh filename="package://autorobo_description/meshes/l298n_1_1.stl" scale="0.001 0.001 0.001"/>
    </geometry>
    <material name="silver"/>
  </visual>
  <collision>
    <origin rpy="0 0 0" xyz="0.015 0.02 -0.022028"/>
    <geometry>
      <mesh filename="package://autorobo_description/meshes/l298n_1_1.stl" scale="0.001 0.001 0.001"/>
    </geometry>
  </collision>
</link>

<link name="l298n2_1_1">
  <inertial>
    <origin rpy="0 0 0" xyz="0.018184118265183506 0.020352210242275227 0.007470505450689356"/>
    <mass value="0.0849456744695859"/>
    <inertia ixx="1.7e-05" ixy="-0.0" ixz="0.0" iyy="1.4e-05" iyz="-3e-06" izz="2.3e-05"/>
  </inertial>
  <visual>
    <origin rpy="0 0 0" xyz="0.015 -0.02 -0.022028"/>
    <geometry>
      <mesh filename="package://autorobo_description/meshes/l298n2_1_1.stl" scale="0.001 0.001 0.001"/>
    </geometry>
    <material name="silver"/>
  </visual>
  <collision>
    <origin rpy="0 0 0" xyz="0.015 -0.02 -0.022028"/>
    <geometry>
      <mesh filename="package://autorobo_description/meshes/l298n2_1_1.stl" scale="0.001 0.001 0.001"/>
    </geometry>
  </collision>
</link>

<link name="FLW_1">
  <inertial>
    <origin rpy="0 0 0" xyz="-0.0003246575514476574 0.0180818788653659 7.012428800204362e-07"/>
    <mass value="0.028921561124240654"/>
    <inertia ixx="1.2e-05" ixy="0.0" ixz="-0.0" iyy="2.2e-05" iyz="-0.0" izz="1.2e-05"/>
  </inertial>
  <visual>
    <origin rpy="0 0 0" xyz="-0.060897 -0.069264 -0.034428"/>
    <geometry>
      <mesh filename="package://autorobo_description/meshes/FLW_1.stl" scale="0.001 0.001 0.001"/>
    </geometry>
    <material name="silver"/>
  </visual>
  <collision>
    <origin rpy="0 0 0" xyz="-0.060897 -0.069264 -0.034428"/>
    <geometry>
      <mesh filename="package://autorobo_description/meshes/FLW_1.stl" scale="0.001 0.001 0.001"/>
    </geometry>
  </collision>
</link>

<link name="BLW_1">
  <inertial>
    <origin rpy="0 0 0" xyz="-0.00014942984579274787 0.018086542383952117 6.849292397966e-05"/>
    <mass value="0.02906916539690974"/>
    <inertia ixx="1.2e-05" ixy="0.0" ixz="-0.0" iyy="2.2e-05" iyz="-0.0" izz="1.2e-05"/>
  </inertial>
  <visual>
    <origin rpy="0 0 0" xyz="0.054803 -0.069264 -0.034428"/>
    <geometry>
      <mesh filename="package://autorobo_description/meshes/BLW_1.stl" scale="0.001 0.001 0.001"/>
    </geometry>
    <material name="silver"/>
  </visual>
  <collision>
    <origin rpy="0 0 0" xyz="0.054803 -0.069264 -0.034428"/>
    <geometry>
      <mesh filename="package://autorobo_description/meshes/BLW_1.stl" scale="0.001 0.001 0.001"/>
    </geometry>
  </collision>
</link>

<link name="BRW_1">
  <inertial>
    <origin rpy="0 0 0" xyz="3.762840989750965e-05 -0.018089450090504333 1.8731276171454758e-05"/>
    <mass value="0.029181940993453677"/>
    <inertia ixx="1.2e-05" ixy="0.0" ixz="0.0" iyy="2.3e-05" iyz="0.0" izz="1.2e-05"/>
  </inertial>
  <visual>
    <origin rpy="0 0 0" xyz="0.054103 0.069936 -0.034428"/>
    <geometry>
      <mesh filename="package://autorobo_description/meshes/BRW_1.stl" scale="0.001 0.001 0.001"/>
    </geometry>
    <material name="silver"/>
  </visual>
  <collision>
    <origin rpy="0 0 0" xyz="0.054103 0.069936 -0.034428"/>
    <geometry>
      <mesh filename="package://autorobo_description/meshes/BRW_1.stl" scale="0.001 0.001 0.001"/>
    </geometry>
  </collision>
</link>

<link name="FRW_1">
  <inertial>
    <origin rpy="0 0 0" xyz="7.591783004595037e-05 -0.0180868048489264 0.00011015800473011816"/>
    <mass value="0.02909738115883565"/>
    <inertia ixx="1.2e-05" ixy="0.0" ixz="0.0" iyy="2.3e-05" iyz="0.0" izz="1.2e-05"/>
  </inertial>
  <visual>
    <origin rpy="0 0 0" xyz="-0.060197 0.069936 -0.034428"/>
    <geometry>
      <mesh filename="package://autorobo_description/meshes/FRW_1.stl" scale="0.001 0.001 0.001"/>
    </geometry>
    <material name="silver"/>
  </visual>
  <collision>
    <origin rpy="0 0 0" xyz="-0.060197 0.069936 -0.034428"/>
    <geometry>
      <mesh filename="package://autorobo_description/meshes/FRW_1.stl" scale="0.001 0.001 0.001"/>
    </geometry>
  </collision>
</link>

<link name="Mid_1_1">
  <inertial>
    <origin rpy="0 0 0" xyz="0.08999979389438593 -0.04999968841815995 0.0019997431370579327"/>
    <mass value="0.24343276346087303"/>
    <inertia ixx="0.000792" ixy="0.0" ixz="0.0" iyy="0.001336" iyz="-0.0" izz="0.002128"/>
  </inertial>
  <visual>
    <origin rpy="0 0 0" xyz="0.086603 -0.049664 -0.081028"/>
    <geometry>
      <mesh filename="package://autorobo_description/meshes/Mid_1_1.stl" scale="0.001 0.001 0.001"/>
    </geometry>
    <material name="silver"/>
  </visual>
  <collision>
    <origin rpy="0 0 0" xyz="0.086603 -0.049664 -0.081028"/>
    <geometry>
      <mesh filename="package://autorobo_description/meshes/Mid_1_1.stl" scale="0.001 0.001 0.001"/>
    </geometry>
  </collision>
</link>

<link name="ST23_1_1">
  <inertial>
    <origin rpy="0 0 0" xyz="0.009999793894385559 -0.019999688418160355 0.029999743137058166"/>
    <mass value="0.04411533406877941"/>
    <inertia ixx="1.4e-05" ixy="0.0" ixz="-0.0" iyy="1.4e-05" iyz="0.0" izz="1e-06"/>
  </inertial>
  <visual>
    <origin rpy="0 0 0" xyz="0.096603 -0.069664 -0.085028"/>
    <geometry>
      <mesh filename="package://autorobo_description/meshes/ST23_1_1.stl" scale="0.001 0.001 0.001"/>
    </geometry>
    <material name="silver"/>
  </visual>
  <collision>
    <origin rpy="0 0 0" xyz="0.096603 -0.069664 -0.085028"/>
    <geometry>
      <mesh filename="package://autorobo_description/meshes/ST23_1_1.stl" scale="0.001 0.001 0.001"/>
    </geometry>
  </collision>
</link>

<link name="ST22_1_1">
  <inertial>
    <origin rpy="0 0 0" xyz="0.009999793894385517 0.020000311581839562 0.029999743137057666"/>
    <mass value="0.044115334068779447"/>
    <inertia ixx="1.4e-05" ixy="0.0" ixz="0.0" iyy="1.4e-05" iyz="0.0" izz="1e-06"/>
  </inertial>
  <visual>
    <origin rpy="0 0 0" xyz="0.096603 0.070336 -0.085028"/>
    <geometry>
      <mesh filename="package://autorobo_description/meshes/ST22_1_1.stl" scale="0.001 0.001 0.001"/>
    </geometry>
    <material name="silver"/>
  </visual>
  <collision>
    <origin rpy="0 0 0" xyz="0.096603 0.070336 -0.085028"/>
    <geometry>
      <mesh filename="package://autorobo_description/meshes/ST22_1_1.stl" scale="0.001 0.001 0.001"/>
    </geometry>
  </collision>
</link>

<link name="ST24_1_1">
  <inertial>
    <origin rpy="0 0 0" xyz="-0.010000206105614348 -0.01999968841816041 0.029999743137058166"/>
    <mass value="0.04411533406877944"/>
    <inertia ixx="1.4e-05" ixy="0.0" ixz="0.0" iyy="1.4e-05" iyz="0.0" izz="1e-06"/>
  </inertial>
  <visual>
    <origin rpy="0 0 0" xyz="-0.103397 -0.069664 -0.085028"/>
    <geometry>
      <mesh filename="package://autorobo_description/meshes/ST24_1_1.stl" scale="0.001 0.001 0.001"/>
    </geometry>
    <material name="silver"/>
  </visual>
  <collision>
    <origin rpy="0 0 0" xyz="-0.103397 -0.069664 -0.085028"/>
    <geometry>
      <mesh filename="package://autorobo_description/meshes/ST24_1_1.stl" scale="0.001 0.001 0.001"/>
    </geometry>
  </collision>
</link>

<link name="ST11_1_1">
  <inertial>
    <origin rpy="0 0 0" xyz="-0.010000206105614487 0.02000031158183989 0.029999743137057628"/>
    <mass value="0.04411533406877941"/>
    <inertia ixx="1.4e-05" ixy="-0.0" ixz="0.0" iyy="1.4e-05" iyz="0.0" izz="1e-06"/>
  </inertial>
  <visual>
    <origin rpy="0 0 0" xyz="-0.103397 0.070336 -0.021028"/>
    <geometry>
      <mesh filename="package://autorobo_description/meshes/ST11_1_1.stl" scale="0.001 0.001 0.001"/>
    </geometry>
    <material name="silver"/>
  </visual>
  <collision>
    <origin rpy="0 0 0" xyz="-0.103397 0.070336 -0.021028"/>
    <geometry>
      <mesh filename="package://autorobo_description/meshes/ST11_1_1.stl" scale="0.001 0.001 0.001"/>
    </geometry>
  </collision>
</link>

<link name="ST21_1_1">
  <inertial>
    <origin rpy="0 0 0" xyz="-0.01000020610561439 0.02000031158183952 0.029999743137057666"/>
    <mass value="0.04411533406877941"/>
    <inertia ixx="1.4e-05" ixy="-0.0" ixz="-0.0" iyy="1.4e-05" iyz="0.0" izz="1e-06"/>
  </inertial>
  <visual>
    <origin rpy="0 0 0" xyz="-0.103397 0.070336 -0.085028"/>
    <geometry>
      <mesh filename="package://autorobo_description/meshes/ST21_1_1.stl" scale="0.001 0.001 0.001"/>
    </geometry>
    <material name="silver"/>
  </visual>
  <collision>
    <origin rpy="0 0 0" xyz="-0.103397 0.070336 -0.085028"/>
    <geometry>
      <mesh filename="package://autorobo_description/meshes/ST21_1_1.stl" scale="0.001 0.001 0.001"/>
    </geometry>
  </collision>
</link>

<link name="RPi_1_1">
  <inertial>
    <origin rpy="0 0 0" xyz="0.015206526891055228 0.07394509884680942 0.01494512361032603"/>
    <mass value="0.15575466194304882"/>
    <inertia ixx="4.8e-05" ixy="1e-06" ixz="1.3e-05" iyy="0.000111" iyz="-1e-06" izz="0.00015"/>
  </inertial>
  <visual>
    <origin rpy="0 0 0" xyz="0.096603 0.070336 -0.085028"/>
    <geometry>
      <mesh filename="package://autorobo_description/meshes/RPi_1_1.stl" scale="0.001 0.001 0.001"/>
    </geometry>
    <material name="silver"/>
  </visual>
  <collision>
    <origin rpy="0 0 0" xyz="0.096603 0.070336 -0.085028"/>
    <geometry>
      <mesh filename="package://autorobo_description/meshes/RPi_1_1.stl" scale="0.001 0.001 0.001"/>
    </geometry>
  </collision>
</link>

<link name="Top_1_1">
  <inertial>
    <origin rpy="0 0 0" xyz="0.08946909280400007 -0.050003074963239746 0.0019997431370579466"/>
    <mass value="0.24224476346087304"/>
    <inertia ixx="0.000792" ixy="0.0" ixz="-0.0" iyy="0.001322" iyz="-0.0" izz="0.002114"/>
  </inertial>
  <visual>
    <origin rpy="0 0 0" xyz="0.086603 -0.049664 -0.145028"/>
    <geometry>
      <mesh filename="package://autorobo_description/meshes/Top_1_1.stl" scale="0.001 0.001 0.001"/>
    </geometry>
    <material name="silver"/>
  </visual>
  <collision>
    <origin rpy="0 0 0" xyz="0.086603 -0.049664 -0.145028"/>
    <geometry>
      <mesh filename="package://autorobo_description/meshes/Top_1_1.stl" scale="0.001 0.001 0.001"/>
    </geometry>
  </collision>
</link>

<link name="DevBoard_1_1">
  <inertial>
    <origin rpy="0 0 0" xyz="-0.038745194968203944 -0.0001675034174409533 0.0188385937620843"/>
    <mass value="0.049762223710507494"/>
    <inertia ixx="1.5e-05" ixy="-0.0" ixz="0.0" iyy="3.8e-05" iyz="-0.0" izz="4.8e-05"/>
  </inertial>
  <visual>
    <origin rpy="0 0 0" xyz="-0.099779 -0.000355 -0.149028"/>
    <geometry>
      <mesh filename="package://autorobo_description/meshes/DevBoard_1_1.stl" scale="0.001 0.001 0.001"/>
    </geometry>
    <material name="silver"/>
  </visual>
  <collision>
    <origin rpy="0 0 0" xyz="-0.099779 -0.000355 -0.149028"/>
    <geometry>
      <mesh filename="package://autorobo_description/meshes/DevBoard_1_1.stl" scale="0.001 0.001 0.001"/>
    </geometry>
  </collision>
</link>

<link name="head_1">
  <inertial>
    <origin rpy="0 0 0" xyz="-0.002169326950683094 -0.00045913391485895424 0.015660649139400185"/>
    <mass value="0.022255320970732673"/>
    <inertia ixx="1e-05" ixy="-0.0" ixz="0.0" iyy="1e-05" iyz="0.0" izz="1.6e-05"/>
  </inertial>
  <visual>
    <origin rpy="0 0 0" xyz="-0.042779 -0.000355 -0.172528"/>
    <geometry>
      <mesh filename="package://autorobo_description/meshes/head_1.stl" scale="0.001 0.001 0.001"/>
    </geometry>
    <material name="silver"/>
  </visual>
  <collision>
    <origin rpy="0 0 0" xyz="-0.042779 -0.000355 -0.172528"/>
    <geometry>
      <mesh filename="package://autorobo_description/meshes/head_1.stl" scale="0.001 0.001 0.001"/>
    </geometry>
  </collision>
</link>

<joint name="Rigid173" type="fixed">
  <origin rpy="0 0 0" xyz="0.103397 0.069664 0.021028"/>
  <parent link="base_link"/>
  <child link="ST14_1_1"/>
</joint>

<joint name="Rigid174" type="fixed">
  <origin rpy="0 0 0" xyz="-0.096603 0.069664 0.021028"/>
  <parent link="base_link"/>
  <child link="ST13_1_1"/>
</joint>

<joint name="Rigid175" type="fixed">
  <origin rpy="0 0 0" xyz="-0.096603 -0.070336 0.021028"/>
  <parent link="base_link"/>
  <child link="ST12_1_1"/>
</joint>

<joint name="Rigid176" type="fixed">
  <origin rpy="0 0 0" xyz="0.003397 -0.000336 0.021028"/>
  <parent link="base_link"/>
  <child link="BRM_1_1"/>
</joint>

<joint name="Rigid177" type="fixed">
  <origin rpy="0 0 0" xyz="0.002697 -0.000336 0.021028"/>
  <parent link="base_link"/>
  <child link="BLM_1_1"/>
</joint>

<joint name="Rigid178" type="fixed">
  <origin rpy="0 0 0" xyz="0.002697 -0.000336 0.021028"/>
  <parent link="base_link"/>
  <child link="FRM_1_1"/>
</joint>

<joint name="Rigid179" type="fixed">
  <origin rpy="0 0 0" xyz="0.003397 -0.000336 0.021028"/>
  <parent link="base_link"/>
  <child link="FLM_1_1"/>
</joint>

<joint name="Rigid180" type="fixed">
  <origin rpy="0 0 0" xyz="-0.015 -0.02 0.022028"/>
  <parent link="base_link"/>
  <child link="l298n_1_1"/>
</joint>

<joint name="Rigid181" type="fixed">
  <origin rpy="0 0 0" xyz="-0.015 0.02 0.022028"/>
  <parent link="base_link"/>
  <child link="l298n2_1_1"/>
</joint>

<joint name="Rev184" type="continuous">
  <origin rpy="0 0 0" xyz="0.0575 0.0696 0.0134"/>
  <parent link="FLM_1_1"/>
  <child link="FLW_1"/>
  <axis xyz="0.0 1.0 0.0"/>
</joint>

<joint name="Rev185" type="continuous">
  <origin rpy="0 0 0" xyz="-0.0575 0.0696 0.0134"/>
  <parent link="BLM_1_1"/>
  <child link="BLW_1"/>
  <axis xyz="0.0 1.0 0.0"/>
</joint>

<joint name="Rev186" type="continuous">
  <origin rpy="0 0 0" xyz="-0.0575 -0.0696 0.0134"/>
  <parent link="BRM_1_1"/>
  <child link="BRW_1"/>
  <axis xyz="-0.0 -1.0 -0.0"/>
</joint>

<joint name="Rev187" type="continuous">
  <origin rpy="0 0 0" xyz="0.0575 -0.0696 0.0134"/>
  <parent link="FRM_1_1"/>
  <child link="FRW_1"/>
  <axis xyz="-0.0 -1.0 -0.0"/>
</joint>

<joint name="Rigid188" type="fixed">
  <origin rpy="0 0 0" xyz="0.01 -0.02 0.06"/>
  <parent link="ST13_1_1"/>
  <child link="Mid_1_1"/>
</joint>

<joint name="Rigid189" type="fixed">
  <origin rpy="0 0 0" xyz="-0.01 0.02 0.004"/>
  <parent link="Mid_1_1"/>
  <child link="ST23_1_1"/>
</joint>

<joint name="Rigid190" type="fixed">
  <origin rpy="0 0 0" xyz="-0.01 -0.12 0.004"/>
  <parent link="Mid_1_1"/>
  <child link="ST22_1_1"/>
</joint>

<joint name="Rigid191" type="fixed">
  <origin rpy="0 0 0" xyz="0.19 0.02 0.004"/>
  <parent link="Mid_1_1"/>
  <child link="ST24_1_1"/>
</joint>

<joint name="Rigid192" type="fixed">
  <origin rpy="0 0 0" xyz="0.103397 -0.070336 0.021028"/>
  <parent link="base_link"/>
  <child link="ST11_1_1"/>
</joint>

<joint name="Rigid193" type="fixed">
  <origin rpy="0 0 0" xyz="0.19 -0.12 0.004"/>
  <parent link="Mid_1_1"/>
  <child link="ST21_1_1"/>
</joint>

<joint name="Rigid194" type="fixed">
  <origin rpy="0 0 0" xyz="-0.01 -0.12 0.004"/>
  <parent link="Mid_1_1"/>
  <child link="RPi_1_1"/>
</joint>

<joint name="Rigid195" type="fixed">
  <origin rpy="0 0 0" xyz="0.01 -0.02 0.06"/>
  <parent link="ST23_1_1"/>
  <child link="Top_1_1"/>
</joint>

<joint name="Rigid196" type="fixed">
  <origin rpy="0 0 0" xyz="0.186382 -0.049309 0.004"/>
  <parent link="Top_1_1"/>
  <child link="DevBoard_1_1"/>
</joint>

<joint name="Rev197" type="continuous">
  <origin rpy="0 0 0" xyz="-0.057 0.0 0.0235"/>
  <parent link="DevBoard_1_1"/>
  <child link="head_1"/>
  <axis xyz="0.0 -0.0 1.0"/>
</joint>

</robot>
